Workbook

Sheet Active Contracts
A1: Player | B1: Tm | C1: 2025-26 | D1: 2026-27 | E1: 2027-28 | F1: 2028-29 | G1: 2029-30 | H1: 2030-31 | I1: Guaranteed | J1: Yrs Left | K1: bbref_id
A2: Stephen Curry | B2: GSW | C2: 59606817 | D2: 62587158 | I2: 122193975 | J2: 2 | K2: curryst01
A3: Joel Embiid | B3: PHI | C3: 55224526 | D3: 58100000 | E3: 62748000 | F3: 67396000 | I3: 176072526 | J3: 4 | K3: embiijo01
A4: Nikola Jokić | B4: DEN | C4: 55224526 | D4: 59033114 | E4: 62841702 | I4: 114257640 | J4: 3 | K4: jokicni01
A5: Kevin Durant | B5: HOU | C5: 54708609 | D5: 43902439 | E5: 46097561 | I5: 98611048 | J5: 3 | K5: duranke01
A6: Jayson Tatum | B6: BOS | C6: 54126450 | D6: 58456566 | E6: 62786682 | F6: 67116798 | G6: 71446914 | I6: 242486496 | J6: 5 | K6: tatumja01
A7: Jimmy Butler | B7: GSW | C7: 54126450 | D7: 56832773 | I7: 110959223 | J7: 2 | K7: butleji01
A8: Giannis Antetokounmpo | B8: MIL | C8: 54126450 | D8: 58456566 | E8: 62786682 | I8: 112583016 | J8: 3 | K8: antetgi01
A9: Anthony Davis | B9: WAS | C9: 54126450 | D9: 58456566 | E9: 62786682 | I9: 112583016 | J9: 3 | K9: davisan02
A10: Devin Booker | B10: PHO | C10: 53142264 | D10: 57078728 | E10: 61015192 | F10: 64065952 | G10: 69191228 | I10: 235302136 | J10: 5 | K10: bookede01
A11: Karl-Anthony Towns | B11: NYK | C11: 53142264 | D11: 57078728 | E11: 61015192 | I11: 110220992 | J11: 3 | K11: townska01
A12: Jaylen Brown | B12: BOS | C12: 53142264 | D12: 57078728 | E12: 61015192 | F12: 64951656 | I12: 236187840 | J12: 4 | K12: brownja02
A13: LeBron James | B13: LAL | C13: 52627153 | I13: 52627153 | J13: 1 | K13: jamesle01
A14: Paul George | B14: PHI | C14: 51666090 | D14: 54126380 | E14: 56586670 | I14: 105792470 | J14: 3 | K14: georgpa01
A15: Kawhi Leonard | B15: LAC | C15: 50000000 | D15: 50300000 | I15: 100300000 | J15: 2 | K15: leonaka01
A16: Zach LaVine | B16: SAC | C16: 47499660 | D16: 48967380 | I16: 47499660 | J16: 2 | K16: lavinza01
A17: Donovan Mitchell | B17: CLE | C17: 46394100 | D17: 50105628 | E17: 53817156 | I17: 96499728 | J17: 3 | K17: mitchdo01
A18: Cade Cunningham | B18: DET | C18: 46394100 | D18: 50105628 | E18: 53817156 | F18: 57528684 | G18: 61240212 | I18: 269085780 | J18: 5 | K18: cunnica01
A19: Trae Young | B19: WAS | C19: 46394100 | D19: 48967380 | I19: 46394100 | J19: 2 | K19: youngtr01
A20: Lauri Markkanen | B20: UTA | C20: 46394100 | D20: 46113154 | E20: 49824681 | F20: 53536209 | I20: 195868144 | J20: 4 | K20: markkla01
A21: Jamal Murray | B21: DEN | C21: 46394100 | D21: 50105628 | E21: 53817156 | F21: 57528684 | I21: 207845568 | J21: 4 | K21: murraja01
A22: Evan Mobley | B22: CLE | C22: 46394100 | D22: 50105628 | E22: 53817156 | F22: 57528684 | G22: 61240212 | I22: 269085780 | J22: 5 | K22: mobleev01
A23: Luka Dončić | B23: LAL | C23: 45999660 | D23: 49800000 | E23: 53784000 | F23: 57768000 | I23: 149583660 | J23: 4 | K23: doncilu01
A24: Anthony Edwards | B24: MIN | C24: 45550512 | D24: 48924624 | E24: 52298736 | F24: 55672848 | I24: 202446720 | J24: 4 | K24: edwaran01
A25: Pascal Siakam | B25: IND | C25: 45550512 | D25: 48924624 | E25: 52298736 | I25: 146773872 | J25: 3 | K25: siakapa01
A26: Tyrese Haliburton | B26: IND | C26: 45550512 | D26: 48924624 | E26: 52298736 | F26: 55672848 | I26: 202446720 | J26: 4 | K26: halibty01
A27: Domantas Sabonis | B27: SAC | C27: 42336000 | D27: 45472000 | E27: 48608000 | I27: 136416000 | J27: 3 | K27: sabondo01
A28: OG Anunoby | B28: NYK | C28: 39568966 | D28: 42500000 | E28: 45431034 | F28: 48362068 | I28: 127500000 | J28: 4 | K28: anunoog01
A29: Zion Williamson | B29: NOP | C29: 39446090 | D29: 42166510 | E29: 44886930 | I29: 126499530 | J29: 3 | K29: willizi01
A30: Ja Morant | B30: MEM | C30: 39446090 | D30: 42166510 | E30: 44886930 | I30: 126499530 | J30: 3 | K30: moranja01
A31: Darius Garland | B31: LAC | C31: 39446090 | D31: 42166510 | E31: 44886930 | I31: 126499530 | J31: 3 | K31: garlada01
A32: James Harden | B32: CLE | C32: 39182693 | D32: 42317307 | J32: 2 | K32: hardeja01
A33: Scottie Barnes | B33: TOR | C33: 38661750 | D33: 41754690 | E33: 44847630 | F33: 47940570 | G33: 51033510 | I33: 224238150 | J33: 5 | K33: barnesc01
A34: Franz Wagner | B34: ORL | C34: 38661750 | D34: 41754690 | E34: 44847630 | F34: 47940570 | G34: 51033510 | I34: 224238150 | J34: 5 | K34: wagnefr01
A35: Shai Gilgeous-Alexander | B35: OKC | C35: 38333050 | D35: 40806150 | E35: 61005000 | F35: 65885400 | G35: 70765800 | H35: 75646200 | I35: 276795400 | J35: 6 | K35: gilgesh01
A36: Michael Porter Jr. | B36: BRK | C36: 38333050 | D36: 40806150 | I36: 50333050 | J36: 2 | K36: portemi01
A37: Brandon Ingram | B37: TOR | C37: 38095238 | D37: 40000000 | E37: 41904762 | I37: 78095238 | J37: 3 | K37: ingrabr01
A38: Tyrese Maxey | B38: PHI | C38: 37958760 | D38: 40770520 | E38: 43582280 | F38: 46394040 | I38: 168705600 | J38: 4 | K38: maxeyty01
A39: LaMelo Ball | B39: CHO | C39: 37958760 | D39: 40770520 | E39: 43582280 | F39: 46394040 | I39: 168705600 | J39: 4 | K39: ballla01
A40: De'Aaron Fox | B40: SAS | C40: 37096620 | D40: 49800000 | E40: 53784000 | F40: 57768000 | G40: 61752000 | I40: 260200620 | J40: 5 | K40: foxde01
...

Sheet Dead Cap
A1: Player | B1: Tm | C1: 2025-26 | D1: Dead Cap Owed | E1: bbref_id
A2: Damian Lillard | B2: POR | C2: 36620603 | D2: 27502800 | E2: lillada01
A3: Deandre Ayton | B3: LAL | C3: 33654814 | D3: 8104000 | E3: aytonde01
A4: Bradley Beal | B4: LAC | C4: 24737010 | D4: 5354000 | E4: bealbr01
A5: Marcus Smart | B5: LAL | C5: 19920855 | D5: 5134000 | E5: smartma01
A6: Blake Wesley | B6: POR | C6: 5643732 | D6: 2296274 | E6: weslebl01
A7: Cole Anthony | B7: PHO | C7: 5996274 | D7: 2296274 | E7: anthoco01
A8: Jordan Clarkson | B8: NYK | C8: 12947835 | D8: 2296274 | E8: clarkjo01
A9: Jevon Carter | B9: ORL | C9: 7680524 | D9: 871000 | E9: carteje01
A10: Kobe Bufkin | B10: LAL | C10: 5480297 | D10: 976577 | E10: bufkiko01
A11: Cam Thomas | B11: MIL | C11: 6837779 | D11: 844607 | E11: thomaca02
A12: Haywood Highsmith | B12: PHO | C12: 6443984 | D12: 1827984 | E12: highsha01
A13: Jeremy Sochan | B13: NYK | C13: 7874853 | D13: 778622 | E13: sochaje01
... A22: Dalano Banton | B22: BOS | C22: 263940 | D22: 131970 | E22: bantoda01

Sheet Team Payroll
A1: Team | B1: Players | C1: 2025-26 Payroll
A2: ATL | B2: =COUNTIF('Active Contracts'!B2:B493,A2) -> 18 | C2: =SUMIF('Active Contracts'!B2:B493,A2,'Active Contracts'!C2:C493) -> 186522162
A3: BOS | B3: =COUNTIF('Active Contracts'!B2:B493,A3) -> 14 | C3: =SUMIF('Active Contracts'!B2:B493,A3,'Active Contracts'!C2:C493) -> 189396596
A4: BRK | B4: =COUNTIF('Active Contracts'!B2:B493,A4) -> 25 | C4: =SUMIF('Active Contracts'!B2:B493,A4,'Active Contracts'!C2:C493) -> 156845832
A5: CHI | B5: =COUNTIF('Active Contracts'!B2:B493,A5) -> 16 | C5: =SUMIF('Active Contracts'!B2:B493,A5,'Active Contracts'!C2:C493) -> 183704631
A6: CHO | B6: =COUNTIF('Active Contracts'!B2:B493,A6) -> 18 | C6: =SUMIF('Active Contracts'!B2:B493,A6,'Active Contracts'!C2:C493) -> 183093722
A7: CLE | B7: =COUNTIF('Active Contracts'!B2:B493,A7) -> 16 | C7: =SUMIF('Active Contracts'!B2:B493,A7,'Active Contracts'!C2:C493) -> 212140929
A8: DAL | B8: =COUNTIF('Active Contracts'!B2:B493,A8) -> 17 | C8: =SUMIF('Active Contracts'!B2:B493,A8,'Active Contracts'!C2:C493) -> 182323774
A9: DEN | B9: =COUNTIF('Active Contracts'!B2:B493,A9) -> 14 | C9: =SUMIF('Active Contracts'!B2:B493,A9,'Active Contracts'!C2:C493) -> 186699349
A10: DET | B10: =COUNTIF('Active Contracts'!B2:B493,A10) -> 17 | C10: =SUMIF('Active Contracts'!B2:B493,A10,'Active Contracts'!C2:C493) -> 185911869
A11: GSW | B11: =COUNTIF('Active Contracts'!B2:B493,A11) -> 14 | C11: =SUMIF('Active Contracts'!B2:B493,A11,'Active Contracts'!C2:C493) -> 204744987
A12: HOU | B12: =COUNTIF('Active Contracts'!B2:B493,A12) -> 14 | C12: =SUMIF('Active Contracts'!B2:B493,A12,'Active Contracts'!C2:C493) -> 194689411
A13: IND | B13: =COUNTIF('Active Contracts'!B2:B493,A13) -> 21 | C13: =SUMIF('Active Contracts'!B2:B493,A13,'Active Contracts'!C2:C493) -> 187970232
A14: LAC | B14: =COUNTIF('Active Contracts'!B2:B493,A14) -> 15 | C14: =SUMIF('Active Contracts'!B2:B493,A14,'Active Contracts'!C2:C493) -> 184762914
A15: LAL | B15: =COUNTIF('Active Contracts'!B2:B493,A15) -> 12 | C15: =SUMIF('Active Contracts'!B2:B493,A15,'Active Contracts'!C2:C493) -> 181082805
A16: MEM | B16: =COUNTIF('Active Contracts'!B2:B493,A16) -> 22 | C16: =SUMIF('Active Contracts'!B2:B493,A16,'Active Contracts'!C2:C493) -> 158365629
A17: MIA | B17: =COUNTIF('Active Contracts'!B2:B493,A17) -> 15 | C17: =SUMIF('Active Contracts'!B2:B493,A17,'Active Contracts'!C2:C493) -> 186447146
A18: MIL | B18: =COUNTIF('Active Contracts'!B2:B493,A18) -> 19 | C18: =SUMIF('Active Contracts'!B2:B493,A18,'Active Contracts'!C2:C493) -> 192313116
A19: MIN | B19: =COUNTIF('Active Contracts'!B2:B493,A19) -> 13 | C19: =SUMIF('Active Contracts'!B2:B493,A19,'Active Contracts'!C2:C493) -> 192749338
A20: NOP | B20: =COUNTIF('Active Contracts'!B2:B493,A20) -> 17 | C20: =SUMIF('Active Contracts'!B2:B493,A20,'Active Contracts'!C2:C493) -> 187616561
A21: NYK | B21: =COUNTIF('Active Contracts'!B2:B493,A21) -> 13 | C21: =SUMIF('Active Contracts'!B2:B493,A21,'Active Contracts'!C2:C493) -> 204379368
A22: OKC | B22: =COUNTIF('Active Contracts'!B2:B493,A22) -> 16 | C22: =SUMIF('Active Contracts'!B2:B493,A22,'Active Contracts'!C2:C493) -> 187450150
A23: ORL | B23: =COUNTIF('Active Contracts'!B2:B493,A23) -> 13 | C23: =SUMIF('Active Contracts'!B2:B493,A23,'Active Contracts'!C2:C493) -> 186471232
A24: PHI | B24: =COUNTIF('Active Contracts'!B2:B493,A24) -> 17 | C24: =SUMIF('Active Contracts'!B2:B493,A24,'Active Contracts'!C2:C493) -> 193496208
A25: PHO | B25: =COUNTIF('Active Contracts'!B2:B493,A25) -> 16 | C25: =SUMIF('Active Contracts'!B2:B493,A25,'Active Contracts'!C2:C493) -> 188522668
A26: POR | B26: =COUNTIF('Active Contracts'!B2:B493,A26) -> 16 | C26: =SUMIF('Active Contracts'!B2:B493,A26,'Active Contracts'!C2:C493) -> 179025488
A27: SAC | B27: =COUNTIF('Active Contracts'!B2:B493,A27) -> 14 | C27: =SUMIF('Active Contracts'!B2:B493,A27,'Active Contracts'!C2:C493) -> 186219931
A28: SAS | B28: =COUNTIF('Active Contracts'!B2:B493,A28) -> 15 | C28: =SUMIF('Active Contracts'!B2:B493,A28,'Active Contracts'!C2:C493) -> 183013457
A29: TOR | B29: =COUNTIF('Active Contracts'!B2:B493,A29) -> 15 | C29: =SUMIF('Active Contracts'!B2:B493,A29,'Active Contracts'!C2:C493) -> 186565404
A30: Tm | B30: =COUNTIF('Active Contracts'!B2:B493,A30) -> 1 | C30: =SUMIF('Active Contracts'!B2:B493,A30,'Active Contracts'!C2:C493) -> 0
A31: UTA | B31: =COUNTIF('Active Contracts'!B2:B493,A31) -> 18 | C31: =SUMIF('Active Contracts'!B2:B493,A31,'Active Contracts'!C2:C493) -> 175065685
A32: WAS | B32: =COUNTIF('Active Contracts'!B2:B493,A32) -> 21 | C32: =SUMIF('Active Contracts'!B2:B493,A32,'Active Contracts'!C2:C493) -> 189893909
A33: TOTAL | B33: =SUM(B2:B32) -> 492 | C33: =SUM(C2:C32) -> 5597484503
